<?xml version="1.0" encoding="UTF-8"?>
<!-- Generated by org.testng.reporters.JUnitReportReporter -->
<testsuite hostname="LAPTOP-PH0174KN" failures="1" tests="7" name="tests.CheckoutTest" time="26.962" errors="0" timestamp="28 Aug 2025 15:29:10 GMT" skipped="6">
  <testcase classname="tests.CheckoutTest" name="testcase5" time="8.559">
    <failure message="expected [58.29] but found [158.29]" type="java.lang.AssertionError">
      <![CDATA[java.lang.AssertionError: expected [58.29] but found [158.29]
at org.testng.Assert.fail(Assert.java:96)
at org.testng.Assert.failNotEquals(Assert.java:776)
at org.testng.Assert.assertEqualsImpl(Assert.java:137)
at org.testng.Assert.assertEquals(Assert.java:118)
at org.testng.Assert.assertEquals(Assert.java:442)
at tests.CheckoutTest.testcase5(CheckoutTest.java:123)
at java.base/jdk.internal.reflect.DirectMethodHandleAccessor.invoke(DirectMethodHandleAccessor.java:103)
at java.base/java.lang.reflect.Method.invoke(Method.java:580)
at org.testng.internal.MethodInvocationHelper.invokeMethod(MethodInvocationHelper.java:124)
at org.testng.internal.Invoker.invokeMethod(Invoker.java:583)
at org.testng.internal.Invoker.retryFailed(Invoker.java:839)
at org.testng.internal.Invoker.invokeTestMethods(Invoker.java:1010)
at org.testng.internal.TestMethodWorker.invokeTestMethods(TestMethodWorker.java:125)
at org.testng.internal.TestMethodWorker.run(TestMethodWorker.java:109)
at org.testng.TestRunner.privateRun(TestRunner.java:648)
at org.testng.TestRunner.run(TestRunner.java:505)
at org.testng.SuiteRunner.runTest(SuiteRunner.java:455)
at org.testng.SuiteRunner.runSequentially(SuiteRunner.java:450)
at org.testng.SuiteRunner.privateRun(SuiteRunner.java:415)
at org.testng.SuiteRunner.run(SuiteRunner.java:364)
at org.testng.SuiteRunnerWorker.runSuite(SuiteRunnerWorker.java:52)
at org.testng.SuiteRunnerWorker.run(SuiteRunnerWorker.java:84)
at org.testng.TestNG.runSuitesSequentially(TestNG.java:1208)
at org.testng.TestNG.runSuitesLocally(TestNG.java:1137)
at org.testng.TestNG.runSuites(TestNG.java:1049)
at org.testng.TestNG.run(TestNG.java:1017)
at org.testng.remote.AbstractRemoteTestNG.run(AbstractRemoteTestNG.java:115)
at org.testng.remote.RemoteTestNG.initAndRun(RemoteTestNG.java:293)
at org.testng.remote.RemoteTestNG.main(RemoteTestNG.java:91)
]]>
    </failure>
  </testcase> <!-- testcase5 -->
  <testcase classname="tests.CheckoutTest" name="testcase5" time="9.496">
    <skipped/>
  </testcase> <!-- testcase5 -->
  <testcase classname="tests.CheckoutTest" name="testcase5" time="8.907">
    <skipped/>
  </testcase> <!-- testcase5 -->
  <testcase classname="tests.CheckoutTest" name="testcase3">
    <skipped/>
  </testcase> <!-- testcase3 -->
  <testcase classname="tests.CheckoutTest" name="testcase2">
    <skipped/>
  </testcase> <!-- testcase2 -->
  <testcase classname="tests.CheckoutTest" name="testcase4">
    <skipped/>
  </testcase> <!-- testcase4 -->
  <testcase classname="tests.CheckoutTest" name="testcase1">
    <skipped/>
  </testcase> <!-- testcase1 -->
</testsuite> <!-- tests.CheckoutTest -->
